[2024-09-26T23:15:51.409+0000] {local_task_job_runner.py:120} INFO - ::group::Pre task execution logs
[2024-09-26T23:15:51.945+0000] {taskinstance.py:2076} INFO - Dependencies all met for dep_context=non-requeueable deps ti=<TaskInstance: example_postgres_pandas_dag_with_decorators.read_data_from_api__1 manual__2024-09-26T23:15:36.296304+00:00 [queued]>
[2024-09-26T23:15:52.089+0000] {taskinstance.py:2076} INFO - Dependencies all met for dep_context=requeueable deps ti=<TaskInstance: example_postgres_pandas_dag_with_decorators.read_data_from_api__1 manual__2024-09-26T23:15:36.296304+00:00 [queued]>
[2024-09-26T23:15:52.103+0000] {taskinstance.py:2306} INFO - Starting attempt 1 of 2
[2024-09-26T23:15:55.220+0000] {taskinstance.py:2330} INFO - Executing <Task(_PythonDecoratedOperator): read_data_from_api__1> on 2024-09-26 23:15:36.296304+00:00
[2024-09-26T23:15:55.401+0000] {standard_task_runner.py:90} INFO - Running: ['***', 'tasks', 'run', 'example_postgres_pandas_dag_with_decorators', 'read_data_from_api__1', 'manual__2024-09-26T23:15:36.296304+00:00', '--job-id', '81', '--raw', '--subdir', 'DAGS_FOLDER/etl_prueba.py', '--cfg-path', '/tmp/tmpf6p15dv5']
[2024-09-26T23:15:55.423+0000] {standard_task_runner.py:91} INFO - Job 81: Subtask read_data_from_api__1
[2024-09-26T23:15:55.642+0000] {logging_mixin.py:188} WARNING - /home/***/.local/lib/python3.12/site-packages/***/task/task_runner/standard_task_runner.py:61 DeprecationWarning: This process (pid=94156) is multi-threaded, use of fork() may lead to deadlocks in the child.
[2024-09-26T23:15:55.643+0000] {standard_task_runner.py:63} INFO - Started process 94168 to run task
[2024-09-26T23:15:56.443+0000] {task_command.py:426} INFO - Running <TaskInstance: example_postgres_pandas_dag_with_decorators.read_data_from_api__1 manual__2024-09-26T23:15:36.296304+00:00 [running]> on host 5e909a8df6c4
[2024-09-26T23:15:57.832+0000] {taskinstance.py:2648} INFO - Exporting env vars: AIRFLOW_CTX_DAG_OWNER='***' AIRFLOW_CTX_DAG_ID='example_postgres_pandas_dag_with_decorators' AIRFLOW_CTX_TASK_ID='read_data_from_api__1' AIRFLOW_CTX_EXECUTION_DATE='2024-09-26T23:15:36.296304+00:00' AIRFLOW_CTX_TRY_NUMBER='1' AIRFLOW_CTX_DAG_RUN_ID='manual__2024-09-26T23:15:36.296304+00:00'
[2024-09-26T23:15:57.836+0000] {taskinstance.py:430} INFO - ::endgroup::
[2024-09-26T23:15:58.668+0000] {logging_mixin.py:188} WARNING - /home/***/.local/lib/python3.12/site-packages/urllib3/connectionpool.py:1103 InsecureRequestWarning: Unverified HTTPS request is being made to host 'api.bcra.gob.ar'. Adding certificate verification is strongly advised. See: https://urllib3.readthedocs.io/en/latest/advanced-usage.html#tls-warnings
[2024-09-26T23:15:58.746+0000] {taskinstance.py:441} INFO - ::group::Post task execution logs
[2024-09-26T23:15:58.760+0000] {taskinstance.py:2905} ERROR - Task failed with exception
Traceback (most recent call last):
  File "/home/airflow/.local/lib/python3.12/site-packages/airflow/models/taskinstance.py", line 465, in _execute_task
    result = _execute_callable(context=context, **execute_callable_kwargs)
             ^^^^^^^^^^^^^^^^^^^^^^^^^^^^^^^^^^^^^^^^^^^^^^^^^^^^^^^^^^^^^
  File "/home/airflow/.local/lib/python3.12/site-packages/airflow/models/taskinstance.py", line 432, in _execute_callable
    return execute_callable(context=context, **execute_callable_kwargs)
           ^^^^^^^^^^^^^^^^^^^^^^^^^^^^^^^^^^^^^^^^^^^^^^^^^^^^^^^^^^^^
  File "/home/airflow/.local/lib/python3.12/site-packages/airflow/models/baseoperator.py", line 400, in wrapper
    return func(self, *args, **kwargs)
           ^^^^^^^^^^^^^^^^^^^^^^^^^^^
  File "/home/airflow/.local/lib/python3.12/site-packages/airflow/decorators/base.py", line 265, in execute
    return_value = super().execute(context)
                   ^^^^^^^^^^^^^^^^^^^^^^^^
  File "/home/airflow/.local/lib/python3.12/site-packages/airflow/models/baseoperator.py", line 400, in wrapper
    return func(self, *args, **kwargs)
           ^^^^^^^^^^^^^^^^^^^^^^^^^^^
  File "/home/airflow/.local/lib/python3.12/site-packages/airflow/operators/python.py", line 235, in execute
    return_value = self.execute_callable()
                   ^^^^^^^^^^^^^^^^^^^^^^^
  File "/home/airflow/.local/lib/python3.12/site-packages/airflow/operators/python.py", line 252, in execute_callable
    return self.python_callable(*self.op_args, **self.op_kwargs)
           ^^^^^^^^^^^^^^^^^^^^^^^^^^^^^^^^^^^^^^^^^^^^^^^^^^^^^
  File "/opt/airflow/dags/etl_prueba.py", line 48, in read_data_from_api
    df.to_sql(TABLA, engine, schema=schema_name, if_exists='replace', index=False)
                     ^^^^^^
NameError: name 'engine' is not defined
[2024-09-26T23:15:58.861+0000] {taskinstance.py:1206} INFO - Marking task as UP_FOR_RETRY. dag_id=example_postgres_pandas_dag_with_decorators, task_id=read_data_from_api__1, run_id=manual__2024-09-26T23:15:36.296304+00:00, execution_date=20240926T231536, start_date=20240926T231551, end_date=20240926T231558
[2024-09-26T23:15:59.058+0000] {standard_task_runner.py:110} ERROR - Failed to execute job 81 for task read_data_from_api__1 (name 'engine' is not defined; 94168)
[2024-09-26T23:15:59.125+0000] {local_task_job_runner.py:240} INFO - Task exited with return code 1
[2024-09-26T23:15:59.333+0000] {taskinstance.py:3498} INFO - 0 downstream tasks scheduled from follow-on schedule check
[2024-09-26T23:15:59.358+0000] {local_task_job_runner.py:222} INFO - ::endgroup::
