[2024-10-02T23:15:06.314+0000] {local_task_job_runner.py:120} INFO - ::group::Pre task execution logs
[2024-10-02T23:15:06.506+0000] {taskinstance.py:2076} INFO - Dependencies all met for dep_context=non-requeueable deps ti=<TaskInstance: process_employees.get_data scheduled__2024-09-29T00:00:00+00:00 [queued]>
[2024-10-02T23:15:06.586+0000] {taskinstance.py:2076} INFO - Dependencies all met for dep_context=requeueable deps ti=<TaskInstance: process_employees.get_data scheduled__2024-09-29T00:00:00+00:00 [queued]>
[2024-10-02T23:15:06.587+0000] {taskinstance.py:2306} INFO - Starting attempt 1 of 1
[2024-10-02T23:15:06.714+0000] {taskinstance.py:2330} INFO - Executing <Task(_PythonDecoratedOperator): get_data> on 2024-09-29 00:00:00+00:00
[2024-10-02T23:15:06.767+0000] {standard_task_runner.py:90} INFO - Running: ['***', 'tasks', 'run', 'process_employees', 'get_data', 'scheduled__2024-09-29T00:00:00+00:00', '--job-id', '220', '--raw', '--subdir', 'DAGS_FOLDER/etl_prueba.py', '--cfg-path', '/tmp/tmp4ah3stc9']
[2024-10-02T23:15:06.787+0000] {standard_task_runner.py:91} INFO - Job 220: Subtask get_data
[2024-10-02T23:15:06.819+0000] {logging_mixin.py:188} WARNING - /home/***/.local/lib/python3.12/site-packages/***/task/task_runner/standard_task_runner.py:61 DeprecationWarning: This process (pid=185) is multi-threaded, use of fork() may lead to deadlocks in the child.
[2024-10-02T23:15:06.820+0000] {standard_task_runner.py:63} INFO - Started process 187 to run task
[2024-10-02T23:15:07.067+0000] {task_command.py:426} INFO - Running <TaskInstance: process_employees.get_data scheduled__2024-09-29T00:00:00+00:00 [running]> on host 5e909a8df6c4
[2024-10-02T23:15:07.543+0000] {taskinstance.py:2648} INFO - Exporting env vars: AIRFLOW_CTX_DAG_OWNER='***' AIRFLOW_CTX_DAG_ID='process_employees' AIRFLOW_CTX_TASK_ID='get_data' AIRFLOW_CTX_EXECUTION_DATE='2024-09-29T00:00:00+00:00' AIRFLOW_CTX_TRY_NUMBER='1' AIRFLOW_CTX_DAG_RUN_ID='scheduled__2024-09-29T00:00:00+00:00'
[2024-10-02T23:15:07.545+0000] {taskinstance.py:430} INFO - ::endgroup::
[2024-10-02T23:15:08.089+0000] {base.py:84} INFO - Using connection ID 'postgres' for task execution.
[2024-10-02T23:15:08.153+0000] {taskinstance.py:441} INFO - ::group::Post task execution logs
[2024-10-02T23:15:08.154+0000] {taskinstance.py:2905} ERROR - Task failed with exception
Traceback (most recent call last):
  File "/home/airflow/.local/lib/python3.12/site-packages/airflow/models/taskinstance.py", line 465, in _execute_task
    result = _execute_callable(context=context, **execute_callable_kwargs)
             ^^^^^^^^^^^^^^^^^^^^^^^^^^^^^^^^^^^^^^^^^^^^^^^^^^^^^^^^^^^^^
  File "/home/airflow/.local/lib/python3.12/site-packages/airflow/models/taskinstance.py", line 432, in _execute_callable
    return execute_callable(context=context, **execute_callable_kwargs)
           ^^^^^^^^^^^^^^^^^^^^^^^^^^^^^^^^^^^^^^^^^^^^^^^^^^^^^^^^^^^^
  File "/home/airflow/.local/lib/python3.12/site-packages/airflow/models/baseoperator.py", line 400, in wrapper
    return func(self, *args, **kwargs)
           ^^^^^^^^^^^^^^^^^^^^^^^^^^^
  File "/home/airflow/.local/lib/python3.12/site-packages/airflow/decorators/base.py", line 265, in execute
    return_value = super().execute(context)
                   ^^^^^^^^^^^^^^^^^^^^^^^^
  File "/home/airflow/.local/lib/python3.12/site-packages/airflow/models/baseoperator.py", line 400, in wrapper
    return func(self, *args, **kwargs)
           ^^^^^^^^^^^^^^^^^^^^^^^^^^^
  File "/home/airflow/.local/lib/python3.12/site-packages/airflow/operators/python.py", line 235, in execute
    return_value = self.execute_callable()
                   ^^^^^^^^^^^^^^^^^^^^^^^
  File "/home/airflow/.local/lib/python3.12/site-packages/airflow/operators/python.py", line 252, in execute_callable
    return self.python_callable(*self.op_args, **self.op_kwargs)
           ^^^^^^^^^^^^^^^^^^^^^^^^^^^^^^^^^^^^^^^^^^^^^^^^^^^^^
  File "/opt/airflow/dags/etl_prueba.py", line 63, in get_data
    cur.copy_expert(
psycopg2.errors.UniqueViolation: duplicate key value violates unique constraint "employees_temp_pkey"
DETAIL:  Key ("Serial Number")=(2) already exists.
CONTEXT:  COPY employees_temp, line 2

[2024-10-02T23:15:08.213+0000] {taskinstance.py:1206} INFO - Marking task as FAILED. dag_id=process_employees, task_id=get_data, run_id=scheduled__2024-09-29T00:00:00+00:00, execution_date=20240929T000000, start_date=20241002T231506, end_date=20241002T231508
[2024-10-02T23:15:08.314+0000] {standard_task_runner.py:110} ERROR - Failed to execute job 220 for task get_data (duplicate key value violates unique constraint "employees_temp_pkey"
DETAIL:  Key ("Serial Number")=(2) already exists.
CONTEXT:  COPY employees_temp, line 2
; 187)
[2024-10-02T23:15:08.342+0000] {local_task_job_runner.py:240} INFO - Task exited with return code 1
[2024-10-02T23:15:08.487+0000] {taskinstance.py:3498} INFO - 0 downstream tasks scheduled from follow-on schedule check
[2024-10-02T23:15:08.516+0000] {local_task_job_runner.py:222} INFO - ::endgroup::
