[2024-09-19T23:17:20.424+0000] {local_task_job_runner.py:120} INFO - ::group::Pre task execution logs
[2024-09-19T23:17:20.801+0000] {taskinstance.py:2076} INFO - Dependencies all met for dep_context=non-requeueable deps ti=<TaskInstance: example_postgres_pandas_dag_with_decorators.read_data_from_api manual__2024-09-19T23:12:03.622447+00:00 [queued]>
[2024-09-19T23:17:20.906+0000] {taskinstance.py:2076} INFO - Dependencies all met for dep_context=requeueable deps ti=<TaskInstance: example_postgres_pandas_dag_with_decorators.read_data_from_api manual__2024-09-19T23:12:03.622447+00:00 [queued]>
[2024-09-19T23:17:20.907+0000] {taskinstance.py:2306} INFO - Starting attempt 2 of 2
[2024-09-19T23:17:21.077+0000] {taskinstance.py:2330} INFO - Executing <Task(_PythonDecoratedOperator): read_data_from_api> on 2024-09-19 23:12:03.622447+00:00
[2024-09-19T23:17:21.315+0000] {standard_task_runner.py:90} INFO - Running: ['***', 'tasks', 'run', 'example_postgres_pandas_dag_with_decorators', 'read_data_from_api', 'manual__2024-09-19T23:12:03.622447+00:00', '--job-id', '64', '--raw', '--subdir', 'DAGS_FOLDER/etl_prueba.py', '--cfg-path', '/tmp/tmpz_nk5k83']
[2024-09-19T23:17:21.341+0000] {logging_mixin.py:188} WARNING - /home/***/.local/lib/python3.12/site-packages/***/task/task_runner/standard_task_runner.py:61 DeprecationWarning: This process (pid=382) is multi-threaded, use of fork() may lead to deadlocks in the child.
[2024-09-19T23:17:21.342+0000] {standard_task_runner.py:63} INFO - Started process 388 to run task
[2024-09-19T23:17:21.335+0000] {standard_task_runner.py:91} INFO - Job 64: Subtask read_data_from_api
[2024-09-19T23:17:21.608+0000] {task_command.py:426} INFO - Running <TaskInstance: example_postgres_pandas_dag_with_decorators.read_data_from_api manual__2024-09-19T23:12:03.622447+00:00 [running]> on host 5e909a8df6c4
[2024-09-19T23:17:22.447+0000] {taskinstance.py:2648} INFO - Exporting env vars: AIRFLOW_CTX_DAG_OWNER='***' AIRFLOW_CTX_DAG_ID='example_postgres_pandas_dag_with_decorators' AIRFLOW_CTX_TASK_ID='read_data_from_api' AIRFLOW_CTX_EXECUTION_DATE='2024-09-19T23:12:03.622447+00:00' AIRFLOW_CTX_TRY_NUMBER='2' AIRFLOW_CTX_DAG_RUN_ID='manual__2024-09-19T23:12:03.622447+00:00'
[2024-09-19T23:17:22.449+0000] {taskinstance.py:430} INFO - ::endgroup::
[2024-09-19T23:17:22.453+0000] {taskinstance.py:441} INFO - ::group::Post task execution logs
[2024-09-19T23:17:22.454+0000] {taskinstance.py:2905} ERROR - Task failed with exception
Traceback (most recent call last):
  File "/home/airflow/.local/lib/python3.12/site-packages/airflow/models/taskinstance.py", line 465, in _execute_task
    result = _execute_callable(context=context, **execute_callable_kwargs)
             ^^^^^^^^^^^^^^^^^^^^^^^^^^^^^^^^^^^^^^^^^^^^^^^^^^^^^^^^^^^^^
  File "/home/airflow/.local/lib/python3.12/site-packages/airflow/models/taskinstance.py", line 432, in _execute_callable
    return execute_callable(context=context, **execute_callable_kwargs)
           ^^^^^^^^^^^^^^^^^^^^^^^^^^^^^^^^^^^^^^^^^^^^^^^^^^^^^^^^^^^^
  File "/home/airflow/.local/lib/python3.12/site-packages/airflow/models/baseoperator.py", line 400, in wrapper
    return func(self, *args, **kwargs)
           ^^^^^^^^^^^^^^^^^^^^^^^^^^^
  File "/home/airflow/.local/lib/python3.12/site-packages/airflow/decorators/base.py", line 265, in execute
    return_value = super().execute(context)
                   ^^^^^^^^^^^^^^^^^^^^^^^^
  File "/home/airflow/.local/lib/python3.12/site-packages/airflow/models/baseoperator.py", line 400, in wrapper
    return func(self, *args, **kwargs)
           ^^^^^^^^^^^^^^^^^^^^^^^^^^^
  File "/home/airflow/.local/lib/python3.12/site-packages/airflow/operators/python.py", line 235, in execute
    return_value = self.execute_callable()
                   ^^^^^^^^^^^^^^^^^^^^^^^
  File "/home/airflow/.local/lib/python3.12/site-packages/airflow/operators/python.py", line 252, in execute_callable
    return self.python_callable(*self.op_args, **self.op_kwargs)
           ^^^^^^^^^^^^^^^^^^^^^^^^^^^^^^^^^^^^^^^^^^^^^^^^^^^^^
  File "/opt/airflow/dags/etl_prueba.py", line 28, in read_data_from_api
    final= datetime.today()- timedelta(1)
                             ^^^^^^^^^
NameError: name 'timedelta' is not defined
[2024-09-19T23:17:22.501+0000] {taskinstance.py:1206} INFO - Marking task as FAILED. dag_id=example_postgres_pandas_dag_with_decorators, task_id=read_data_from_api, run_id=manual__2024-09-19T23:12:03.622447+00:00, execution_date=20240919T231203, start_date=20240919T231720, end_date=20240919T231722
[2024-09-19T23:17:22.576+0000] {standard_task_runner.py:110} ERROR - Failed to execute job 64 for task read_data_from_api (name 'timedelta' is not defined; 388)
[2024-09-19T23:17:22.642+0000] {local_task_job_runner.py:240} INFO - Task exited with return code 1
[2024-09-19T23:17:22.701+0000] {local_task_job_runner.py:222} INFO - ::endgroup::
