[2024-09-27T15:59:42.579+0000] {local_task_job_runner.py:120} INFO - ::group::Pre task execution logs
[2024-09-27T15:59:43.260+0000] {taskinstance.py:2076} INFO - Dependencies all met for dep_context=non-requeueable deps ti=<TaskInstance: example_postgres_pandas_dag_with_decorators.read_data_from_api manual__2024-09-27T15:59:23.880100+00:00 [queued]>
[2024-09-27T15:59:43.377+0000] {taskinstance.py:2076} INFO - Dependencies all met for dep_context=requeueable deps ti=<TaskInstance: example_postgres_pandas_dag_with_decorators.read_data_from_api manual__2024-09-27T15:59:23.880100+00:00 [queued]>
[2024-09-27T15:59:43.379+0000] {taskinstance.py:2306} INFO - Starting attempt 1 of 1
[2024-09-27T15:59:45.288+0000] {taskinstance.py:2330} INFO - Executing <Task(_PythonDecoratedOperator): read_data_from_api> on 2024-09-27 15:59:23.880100+00:00
[2024-09-27T15:59:45.373+0000] {standard_task_runner.py:90} INFO - Running: ['***', 'tasks', 'run', 'example_postgres_pandas_dag_with_decorators', 'read_data_from_api', 'manual__2024-09-27T15:59:23.880100+00:00', '--job-id', '125', '--raw', '--subdir', 'DAGS_FOLDER/etl_prueba.py', '--cfg-path', '/tmp/tmpnqe59fwc']
[2024-09-27T15:59:45.438+0000] {standard_task_runner.py:91} INFO - Job 125: Subtask read_data_from_api
[2024-09-27T15:59:45.497+0000] {logging_mixin.py:188} WARNING - /home/***/.local/lib/python3.12/site-packages/***/task/task_runner/standard_task_runner.py:61 DeprecationWarning: This process (pid=337) is multi-threaded, use of fork() may lead to deadlocks in the child.
[2024-09-27T15:59:45.551+0000] {standard_task_runner.py:63} INFO - Started process 341 to run task
[2024-09-27T15:59:46.108+0000] {task_command.py:426} INFO - Running <TaskInstance: example_postgres_pandas_dag_with_decorators.read_data_from_api manual__2024-09-27T15:59:23.880100+00:00 [running]> on host 5e909a8df6c4
[2024-09-27T15:59:47.462+0000] {taskinstance.py:2648} INFO - Exporting env vars: AIRFLOW_CTX_DAG_OWNER='***' AIRFLOW_CTX_DAG_ID='example_postgres_pandas_dag_with_decorators' AIRFLOW_CTX_TASK_ID='read_data_from_api' AIRFLOW_CTX_EXECUTION_DATE='2024-09-27T15:59:23.880100+00:00' AIRFLOW_CTX_TRY_NUMBER='1' AIRFLOW_CTX_DAG_RUN_ID='manual__2024-09-27T15:59:23.880100+00:00'
[2024-09-27T15:59:47.466+0000] {taskinstance.py:430} INFO - ::endgroup::
[2024-09-27T15:59:47.628+0000] {taskinstance.py:441} INFO - ::group::Post task execution logs
[2024-09-27T15:59:47.885+0000] {taskinstance.py:2905} ERROR - Task failed with exception
Traceback (most recent call last):
  File "/home/airflow/.local/lib/python3.12/site-packages/airflow/models/taskinstance.py", line 465, in _execute_task
    result = _execute_callable(context=context, **execute_callable_kwargs)
             ^^^^^^^^^^^^^^^^^^^^^^^^^^^^^^^^^^^^^^^^^^^^^^^^^^^^^^^^^^^^^
  File "/home/airflow/.local/lib/python3.12/site-packages/airflow/models/taskinstance.py", line 432, in _execute_callable
    return execute_callable(context=context, **execute_callable_kwargs)
           ^^^^^^^^^^^^^^^^^^^^^^^^^^^^^^^^^^^^^^^^^^^^^^^^^^^^^^^^^^^^
  File "/home/airflow/.local/lib/python3.12/site-packages/airflow/models/baseoperator.py", line 400, in wrapper
    return func(self, *args, **kwargs)
           ^^^^^^^^^^^^^^^^^^^^^^^^^^^
  File "/home/airflow/.local/lib/python3.12/site-packages/airflow/decorators/base.py", line 265, in execute
    return_value = super().execute(context)
                   ^^^^^^^^^^^^^^^^^^^^^^^^
  File "/home/airflow/.local/lib/python3.12/site-packages/airflow/models/baseoperator.py", line 400, in wrapper
    return func(self, *args, **kwargs)
           ^^^^^^^^^^^^^^^^^^^^^^^^^^^
  File "/home/airflow/.local/lib/python3.12/site-packages/airflow/operators/python.py", line 235, in execute
    return_value = self.execute_callable()
                   ^^^^^^^^^^^^^^^^^^^^^^^
  File "/home/airflow/.local/lib/python3.12/site-packages/airflow/operators/python.py", line 252, in execute_callable
    return self.python_callable(*self.op_args, **self.op_kwargs)
           ^^^^^^^^^^^^^^^^^^^^^^^^^^^^^^^^^^^^^^^^^^^^^^^^^^^^^
  File "/opt/airflow/dags/etl_prueba.py", line 34, in read_data_from_api
    connection_uri = hook.get_uri()
                     ^^^^^^^^^^^^^^
  File "/home/airflow/.local/lib/python3.12/site-packages/airflow/providers/postgres/hooks/postgres.py", line 190, in get_uri
    conn = self.get_connection(getattr(self, self.conn_name_attr))
           ^^^^^^^^^^^^^^^^^^^^^^^^^^^^^^^^^^^^^^^^^^^^^^^^^^^^^^^
  File "/home/airflow/.local/lib/python3.12/site-packages/airflow/hooks/base.py", line 83, in get_connection
    conn = Connection.get_connection_from_secrets(conn_id)
           ^^^^^^^^^^^^^^^^^^^^^^^^^^^^^^^^^^^^^^^^^^^^^^^
  File "/home/airflow/.local/lib/python3.12/site-packages/airflow/models/connection.py", line 519, in get_connection_from_secrets
    raise AirflowNotFoundException(f"The conn_id `{conn_id}` isn't defined")
airflow.exceptions.AirflowNotFoundException: The conn_id `postgres_default` isn't defined
[2024-09-27T15:59:48.035+0000] {taskinstance.py:1206} INFO - Marking task as FAILED. dag_id=example_postgres_pandas_dag_with_decorators, task_id=read_data_from_api, run_id=manual__2024-09-27T15:59:23.880100+00:00, execution_date=20240927T155923, start_date=20240927T155943, end_date=20240927T155948
[2024-09-27T15:59:48.258+0000] {standard_task_runner.py:110} ERROR - Failed to execute job 125 for task read_data_from_api (The conn_id `postgres_default` isn't defined; 341)
[2024-09-27T15:59:48.399+0000] {local_task_job_runner.py:240} INFO - Task exited with return code 1
[2024-09-27T15:59:48.692+0000] {taskinstance.py:3498} INFO - 0 downstream tasks scheduled from follow-on schedule check
[2024-09-27T15:59:48.766+0000] {local_task_job_runner.py:222} INFO - ::endgroup::
