[2024-10-04T20:54:08.029+0000] {local_task_job_runner.py:120} INFO - ::group::Pre task execution logs
[2024-10-04T20:54:08.154+0000] {taskinstance.py:2076} INFO - Dependencies all met for dep_context=non-requeueable deps ti=<TaskInstance: process_employees.merge_data manual__2024-10-04T20:53:39.815214+00:00 [queued]>
[2024-10-04T20:54:08.196+0000] {taskinstance.py:2076} INFO - Dependencies all met for dep_context=requeueable deps ti=<TaskInstance: process_employees.merge_data manual__2024-10-04T20:53:39.815214+00:00 [queued]>
[2024-10-04T20:54:08.197+0000] {taskinstance.py:2306} INFO - Starting attempt 1 of 1
[2024-10-04T20:54:08.800+0000] {taskinstance.py:2330} INFO - Executing <Task(_PythonDecoratedOperator): merge_data> on 2024-10-04 20:53:39.815214+00:00
[2024-10-04T20:54:08.840+0000] {standard_task_runner.py:90} INFO - Running: ['***', 'tasks', 'run', 'process_employees', 'merge_data', 'manual__2024-10-04T20:53:39.815214+00:00', '--job-id', '274', '--raw', '--subdir', 'DAGS_FOLDER/etl_prueba.py', '--cfg-path', '/tmp/tmp93c11gxq']
[2024-10-04T20:54:08.849+0000] {standard_task_runner.py:91} INFO - Job 274: Subtask merge_data
[2024-10-04T20:54:08.867+0000] {logging_mixin.py:188} WARNING - /home/***/.local/lib/python3.12/site-packages/***/task/task_runner/standard_task_runner.py:61 DeprecationWarning: This process (pid=454) is multi-threaded, use of fork() may lead to deadlocks in the child.
[2024-10-04T20:54:08.868+0000] {standard_task_runner.py:63} INFO - Started process 462 to run task
[2024-10-04T20:54:09.091+0000] {task_command.py:426} INFO - Running <TaskInstance: process_employees.merge_data manual__2024-10-04T20:53:39.815214+00:00 [running]> on host 5e909a8df6c4
[2024-10-04T20:54:09.389+0000] {taskinstance.py:2648} INFO - Exporting env vars: AIRFLOW_CTX_DAG_OWNER='***' AIRFLOW_CTX_DAG_ID='process_employees' AIRFLOW_CTX_TASK_ID='merge_data' AIRFLOW_CTX_EXECUTION_DATE='2024-10-04T20:53:39.815214+00:00' AIRFLOW_CTX_TRY_NUMBER='1' AIRFLOW_CTX_DAG_RUN_ID='manual__2024-10-04T20:53:39.815214+00:00'
[2024-10-04T20:54:09.404+0000] {taskinstance.py:430} INFO - ::endgroup::
[2024-10-04T20:54:09.456+0000] {base.py:84} INFO - Using connection ID 'postgres' for task execution.
[2024-10-04T20:54:09.492+0000] {taskinstance.py:441} INFO - ::group::Post task execution logs
[2024-10-04T20:54:09.494+0000] {taskinstance.py:2905} ERROR - Task failed with exception
Traceback (most recent call last):
  File "/home/airflow/.local/lib/python3.12/site-packages/airflow/models/taskinstance.py", line 465, in _execute_task
    result = _execute_callable(context=context, **execute_callable_kwargs)
             ^^^^^^^^^^^^^^^^^^^^^^^^^^^^^^^^^^^^^^^^^^^^^^^^^^^^^^^^^^^^^
  File "/home/airflow/.local/lib/python3.12/site-packages/airflow/models/taskinstance.py", line 432, in _execute_callable
    return execute_callable(context=context, **execute_callable_kwargs)
           ^^^^^^^^^^^^^^^^^^^^^^^^^^^^^^^^^^^^^^^^^^^^^^^^^^^^^^^^^^^^
  File "/home/airflow/.local/lib/python3.12/site-packages/airflow/models/baseoperator.py", line 400, in wrapper
    return func(self, *args, **kwargs)
           ^^^^^^^^^^^^^^^^^^^^^^^^^^^
  File "/home/airflow/.local/lib/python3.12/site-packages/airflow/decorators/base.py", line 265, in execute
    return_value = super().execute(context)
                   ^^^^^^^^^^^^^^^^^^^^^^^^
  File "/home/airflow/.local/lib/python3.12/site-packages/airflow/models/baseoperator.py", line 400, in wrapper
    return func(self, *args, **kwargs)
           ^^^^^^^^^^^^^^^^^^^^^^^^^^^
  File "/home/airflow/.local/lib/python3.12/site-packages/airflow/operators/python.py", line 235, in execute
    return_value = self.execute_callable()
                   ^^^^^^^^^^^^^^^^^^^^^^^
  File "/home/airflow/.local/lib/python3.12/site-packages/airflow/operators/python.py", line 252, in execute_callable
    return self.python_callable(*self.op_args, **self.op_kwargs)
           ^^^^^^^^^^^^^^^^^^^^^^^^^^^^^^^^^^^^^^^^^^^^^^^^^^^^^
  File "/opt/airflow/dags/etl_prueba.py", line 88, in merge_data
    cur.copy_expert(
psycopg2.errors.UniqueViolation: duplicate key value violates unique constraint "reservas_temp_pkey"
DETAIL:  Key ("idVariable")=(1) already exists.
CONTEXT:  COPY reservas_temp, line 3

[2024-10-04T20:54:09.546+0000] {taskinstance.py:1206} INFO - Marking task as FAILED. dag_id=process_employees, task_id=merge_data, run_id=manual__2024-10-04T20:53:39.815214+00:00, execution_date=20241004T205339, start_date=20241004T205408, end_date=20241004T205409
[2024-10-04T20:54:09.663+0000] {standard_task_runner.py:110} ERROR - Failed to execute job 274 for task merge_data (duplicate key value violates unique constraint "reservas_temp_pkey"
DETAIL:  Key ("idVariable")=(1) already exists.
CONTEXT:  COPY reservas_temp, line 3
; 462)
[2024-10-04T20:54:09.730+0000] {local_task_job_runner.py:240} INFO - Task exited with return code 1
[2024-10-04T20:54:09.796+0000] {taskinstance.py:3498} INFO - 0 downstream tasks scheduled from follow-on schedule check
[2024-10-04T20:54:09.816+0000] {local_task_job_runner.py:222} INFO - ::endgroup::
