[2024-11-30T23:53:32.364+0000] {local_task_job_runner.py:120} INFO - ::group::Pre task execution logs
[2024-11-30T23:53:32.886+0000] {taskinstance.py:2076} INFO - Dependencies all met for dep_context=non-requeueable deps ti=<TaskInstance: process_variables_financieras.consumo_stg_var1_reservas manual__2024-11-30T23:53:14.329418+00:00 [queued]>
[2024-11-30T23:53:33.015+0000] {taskinstance.py:2076} INFO - Dependencies all met for dep_context=requeueable deps ti=<TaskInstance: process_variables_financieras.consumo_stg_var1_reservas manual__2024-11-30T23:53:14.329418+00:00 [queued]>
[2024-11-30T23:53:33.020+0000] {taskinstance.py:2306} INFO - Starting attempt 1 of 1
[2024-11-30T23:53:34.719+0000] {taskinstance.py:2330} INFO - Executing <Task(_PythonDecoratedOperator): consumo_stg_var1_reservas> on 2024-11-30 23:53:14.329418+00:00
[2024-11-30T23:53:34.785+0000] {standard_task_runner.py:90} INFO - Running: ['***', 'tasks', 'run', 'process_variables_financieras', 'consumo_stg_var1_reservas', 'manual__2024-11-30T23:53:14.329418+00:00', '--job-id', '375', '--raw', '--subdir', 'DAGS_FOLDER/etl_prueba.py', '--cfg-path', '/tmp/tmpcrbfbbpn']
[2024-11-30T23:53:34.852+0000] {standard_task_runner.py:91} INFO - Job 375: Subtask consumo_stg_var1_reservas
[2024-11-30T23:53:34.879+0000] {logging_mixin.py:188} WARNING - /home/***/.local/lib/python3.12/site-packages/***/task/task_runner/standard_task_runner.py:61 DeprecationWarning: This process (pid=2086) is multi-threaded, use of fork() may lead to deadlocks in the child.
[2024-11-30T23:53:34.907+0000] {standard_task_runner.py:63} INFO - Started process 2092 to run task
[2024-11-30T23:53:35.504+0000] {task_command.py:426} INFO - Running <TaskInstance: process_variables_financieras.consumo_stg_var1_reservas manual__2024-11-30T23:53:14.329418+00:00 [running]> on host 5e909a8df6c4
[2024-11-30T23:53:36.592+0000] {taskinstance.py:2648} INFO - Exporting env vars: AIRFLOW_CTX_DAG_OWNER='***' AIRFLOW_CTX_DAG_ID='process_variables_financieras' AIRFLOW_CTX_TASK_ID='consumo_stg_var1_reservas' AIRFLOW_CTX_EXECUTION_DATE='2024-11-30T23:53:14.329418+00:00' AIRFLOW_CTX_TRY_NUMBER='1' AIRFLOW_CTX_DAG_RUN_ID='manual__2024-11-30T23:53:14.329418+00:00'
[2024-11-30T23:53:36.600+0000] {taskinstance.py:430} INFO - ::endgroup::
[2024-11-30T23:53:36.604+0000] {taskinstance.py:441} INFO - ::group::Post task execution logs
[2024-11-30T23:53:36.614+0000] {taskinstance.py:2905} ERROR - Task failed with exception
Traceback (most recent call last):
  File "/home/airflow/.local/lib/python3.12/site-packages/airflow/models/taskinstance.py", line 465, in _execute_task
    result = _execute_callable(context=context, **execute_callable_kwargs)
             ^^^^^^^^^^^^^^^^^^^^^^^^^^^^^^^^^^^^^^^^^^^^^^^^^^^^^^^^^^^^^
  File "/home/airflow/.local/lib/python3.12/site-packages/airflow/models/taskinstance.py", line 432, in _execute_callable
    return execute_callable(context=context, **execute_callable_kwargs)
           ^^^^^^^^^^^^^^^^^^^^^^^^^^^^^^^^^^^^^^^^^^^^^^^^^^^^^^^^^^^^
  File "/home/airflow/.local/lib/python3.12/site-packages/airflow/models/baseoperator.py", line 400, in wrapper
    return func(self, *args, **kwargs)
           ^^^^^^^^^^^^^^^^^^^^^^^^^^^
  File "/home/airflow/.local/lib/python3.12/site-packages/airflow/decorators/base.py", line 265, in execute
    return_value = super().execute(context)
                   ^^^^^^^^^^^^^^^^^^^^^^^^
  File "/home/airflow/.local/lib/python3.12/site-packages/airflow/models/baseoperator.py", line 400, in wrapper
    return func(self, *args, **kwargs)
           ^^^^^^^^^^^^^^^^^^^^^^^^^^^
  File "/home/airflow/.local/lib/python3.12/site-packages/airflow/operators/python.py", line 235, in execute
    return_value = self.execute_callable()
                   ^^^^^^^^^^^^^^^^^^^^^^^
  File "/home/airflow/.local/lib/python3.12/site-packages/airflow/operators/python.py", line 252, in execute_callable
    return self.python_callable(*self.op_args, **self.op_kwargs)
           ^^^^^^^^^^^^^^^^^^^^^^^^^^^^^^^^^^^^^^^^^^^^^^^^^^^^^
  File "/opt/airflow/dags/etl_prueba.py", line 41, in consumo_stg_var1_reservas
    ConsumoArchivo("reservas.csv","var_1_reservas_usd")
    ^^^^^^^^^^^^^^
NameError: name 'ConsumoArchivo' is not defined
[2024-11-30T23:53:36.742+0000] {taskinstance.py:1206} INFO - Marking task as FAILED. dag_id=process_variables_financieras, task_id=consumo_stg_var1_reservas, run_id=manual__2024-11-30T23:53:14.329418+00:00, execution_date=20241130T235314, start_date=20241130T235332, end_date=20241130T235336
[2024-11-30T23:53:36.884+0000] {standard_task_runner.py:110} ERROR - Failed to execute job 375 for task consumo_stg_var1_reservas (name 'ConsumoArchivo' is not defined; 2092)
[2024-11-30T23:53:36.938+0000] {local_task_job_runner.py:240} INFO - Task exited with return code 1
[2024-11-30T23:53:37.034+0000] {taskinstance.py:3498} INFO - 0 downstream tasks scheduled from follow-on schedule check
[2024-11-30T23:53:37.066+0000] {local_task_job_runner.py:222} INFO - ::endgroup::
