[2024-09-27T00:24:10.746+0000] {local_task_job_runner.py:120} INFO - ::group::Pre task execution logs
[2024-09-27T00:24:10.961+0000] {taskinstance.py:2076} INFO - Dependencies all met for dep_context=non-requeueable deps ti=<TaskInstance: example_postgres_pandas_dag_with_decorators.read_data_from_api manual__2024-09-27T00:24:04.873488+00:00 [queued]>
[2024-09-27T00:24:11.014+0000] {taskinstance.py:2076} INFO - Dependencies all met for dep_context=requeueable deps ti=<TaskInstance: example_postgres_pandas_dag_with_decorators.read_data_from_api manual__2024-09-27T00:24:04.873488+00:00 [queued]>
[2024-09-27T00:24:11.015+0000] {taskinstance.py:2306} INFO - Starting attempt 1 of 1
[2024-09-27T00:24:11.105+0000] {taskinstance.py:2330} INFO - Executing <Task(_PythonDecoratedOperator): read_data_from_api> on 2024-09-27 00:24:04.873488+00:00
[2024-09-27T00:24:11.216+0000] {logging_mixin.py:188} WARNING - /home/***/.local/lib/python3.12/site-packages/***/task/task_runner/standard_task_runner.py:61 DeprecationWarning: This process (pid=95776) is multi-threaded, use of fork() may lead to deadlocks in the child.
[2024-09-27T00:24:11.218+0000] {standard_task_runner.py:63} INFO - Started process 95778 to run task
[2024-09-27T00:24:11.139+0000] {standard_task_runner.py:90} INFO - Running: ['***', 'tasks', 'run', 'example_postgres_pandas_dag_with_decorators', 'read_data_from_api', 'manual__2024-09-27T00:24:04.873488+00:00', '--job-id', '111', '--raw', '--subdir', 'DAGS_FOLDER/etl_prueba.py', '--cfg-path', '/tmp/tmp_7frfmx6']
[2024-09-27T00:24:12.398+0000] {standard_task_runner.py:91} INFO - Job 111: Subtask read_data_from_api
[2024-09-27T00:24:12.636+0000] {task_command.py:426} INFO - Running <TaskInstance: example_postgres_pandas_dag_with_decorators.read_data_from_api manual__2024-09-27T00:24:04.873488+00:00 [running]> on host 5e909a8df6c4
[2024-09-27T00:24:13.149+0000] {taskinstance.py:2648} INFO - Exporting env vars: AIRFLOW_CTX_DAG_OWNER='***' AIRFLOW_CTX_DAG_ID='example_postgres_pandas_dag_with_decorators' AIRFLOW_CTX_TASK_ID='read_data_from_api' AIRFLOW_CTX_EXECUTION_DATE='2024-09-27T00:24:04.873488+00:00' AIRFLOW_CTX_TRY_NUMBER='1' AIRFLOW_CTX_DAG_RUN_ID='manual__2024-09-27T00:24:04.873488+00:00'
[2024-09-27T00:24:13.151+0000] {taskinstance.py:430} INFO - ::endgroup::
[2024-09-27T00:24:13.196+0000] {base.py:84} INFO - Using connection ID 'postgres' for task execution.
[2024-09-27T00:24:13.197+0000] {taskinstance.py:441} INFO - ::group::Post task execution logs
[2024-09-27T00:24:13.198+0000] {taskinstance.py:2905} ERROR - Task failed with exception
Traceback (most recent call last):
  File "/home/airflow/.local/lib/python3.12/site-packages/airflow/models/taskinstance.py", line 465, in _execute_task
    result = _execute_callable(context=context, **execute_callable_kwargs)
             ^^^^^^^^^^^^^^^^^^^^^^^^^^^^^^^^^^^^^^^^^^^^^^^^^^^^^^^^^^^^^
  File "/home/airflow/.local/lib/python3.12/site-packages/airflow/models/taskinstance.py", line 432, in _execute_callable
    return execute_callable(context=context, **execute_callable_kwargs)
           ^^^^^^^^^^^^^^^^^^^^^^^^^^^^^^^^^^^^^^^^^^^^^^^^^^^^^^^^^^^^
  File "/home/airflow/.local/lib/python3.12/site-packages/airflow/models/baseoperator.py", line 400, in wrapper
    return func(self, *args, **kwargs)
           ^^^^^^^^^^^^^^^^^^^^^^^^^^^
  File "/home/airflow/.local/lib/python3.12/site-packages/airflow/decorators/base.py", line 265, in execute
    return_value = super().execute(context)
                   ^^^^^^^^^^^^^^^^^^^^^^^^
  File "/home/airflow/.local/lib/python3.12/site-packages/airflow/models/baseoperator.py", line 400, in wrapper
    return func(self, *args, **kwargs)
           ^^^^^^^^^^^^^^^^^^^^^^^^^^^
  File "/home/airflow/.local/lib/python3.12/site-packages/airflow/operators/python.py", line 235, in execute
    return_value = self.execute_callable()
                   ^^^^^^^^^^^^^^^^^^^^^^^
  File "/home/airflow/.local/lib/python3.12/site-packages/airflow/operators/python.py", line 252, in execute_callable
    return self.python_callable(*self.op_args, **self.op_kwargs)
           ^^^^^^^^^^^^^^^^^^^^^^^^^^^^^^^^^^^^^^^^^^^^^^^^^^^^^
  File "/opt/airflow/dags/etl_prueba.py", line 37, in read_data_from_api
    engine = create_engine(connection_uri)
             ^^^^^^^^^^^^^
NameError: name 'create_engine' is not defined
[2024-09-27T00:24:13.321+0000] {taskinstance.py:1206} INFO - Marking task as FAILED. dag_id=example_postgres_pandas_dag_with_decorators, task_id=read_data_from_api, run_id=manual__2024-09-27T00:24:04.873488+00:00, execution_date=20240927T002404, start_date=20240927T002410, end_date=20240927T002413
[2024-09-27T00:24:13.460+0000] {standard_task_runner.py:110} ERROR - Failed to execute job 111 for task read_data_from_api (name 'create_engine' is not defined; 95778)
[2024-09-27T00:24:13.607+0000] {local_task_job_runner.py:240} INFO - Task exited with return code 1
[2024-09-27T00:24:14.504+0000] {local_task_job_runner.py:222} INFO - ::endgroup::
